<?xml version="1.0" ?>
<!-- =================================================================================== -->
<!-- |    This document was autogenerated by xacro from src/rover_description/urdf/rover.urdf.xacro | -->
<!-- |    EDITING THIS FILE BY HAND IS NOT RECOMMENDED                                 | -->
<!-- =================================================================================== -->
<robot name="rover">
  <material name="body_color">
    <color rgba="0.615686 0.811765 0.929412 1"/>
  </material>
  <!-- body -->
  <link name="base_link"/>
  <link name="main_body">
    <inertial>
      <origin rpy="0 0 0" xyz="-0.077841 0.00218182 -0.0645442"/>
      <mass value="0.00344468"/>
      <inertia ixx="8.31262e-06" ixy="1.21351e-08" ixz="-4.30308e-07" iyy="2.83262e-05" iyz="7.87963e-09" izz="3.34903e-05"/>
    </inertial>
    <visual>
      <origin rpy="0 0 0" xyz="8.67362e-19 0.00232656 -0.028"/>
      <geometry>
        <mesh filename="package://rover_description/meshes/59.stl" scale="1 1 1"/>
      </geometry>
      <material name="body_color"/>
    </visual>
    <collision>
      <origin rpy="0 0 0" xyz="8.67362e-19 0.00232656 -0.028"/>
      <geometry>
        <mesh filename="package://rover_description/meshes/59.stl" scale="1 1 1"/>
      </geometry>
    </collision>
  </link>
  <joint name="base_to_body" type="fixed">
    <origin rpy="0 0 0" xyz="0 0 0"/>
    <parent link="base_link"/>
    <child link="main_body"/>
  </joint>
  <link name="wheel_2">
    <inertial>
      <origin rpy="0 0 0" xyz="0.0143801 0 -0.00317342"/>
      <mass value="0.000126179"/>
      <inertia ixx="1.35094e-07" ixy="0" ixz="4.8002e-11" iyy="7.41754e-08" iyz="0" izz="7.43953e-08"/>
    </inertial>
    <visual>
      <origin rpy="0 0 0" xyz="0.001 0 0"/>
      <geometry>
        <mesh filename="package://rover_description/meshes/63.stl" scale="1 1 1"/>
      </geometry>
      <material name="body_color"/>
    </visual>
    <collision>
      <origin rpy="0 0 0" xyz="0.001 0 0"/>
      <geometry>
        <mesh filename="package://rover_description/meshes/63.stl" scale="1 1 1"/>
      </geometry>
    </collision>
  </link>
  <joint name="wheel_2_joint" type="continuous">
    <origin rpy="0.998696 0 1.5708" xyz="-0.165821 -0.109219 -0.0805"/>
    <axis xyz="-1 0 0"/>
    <parent link="main_body"/>
    <child link="wheel_2"/>
  </joint>
  <gazebo reference="wheel_2">
    <mu1>1.0</mu1>
    <mu2>1.0</mu2>
    <kp>100000.0</kp>
    <kd>1.0</kd>
  </gazebo>
  <link name="wheel_1">
    <inertial>
      <origin rpy="0 0 0" xyz="0.0143801 0 -0.00317342"/>
      <mass value="0.000126179"/>
      <inertia ixx="1.35094e-07" ixy="0" ixz="4.8002e-11" iyy="7.41754e-08" iyz="0" izz="7.43953e-08"/>
    </inertial>
    <visual>
      <origin rpy="0 0 0" xyz="0.001 0 0"/>
      <geometry>
        <mesh filename="package://rover_description/meshes/63.stl" scale="1 1 1"/>
      </geometry>
      <material name="body_color"/>
    </visual>
    <collision>
      <origin rpy="0 0 0" xyz="0.001 0 0"/>
      <geometry>
        <mesh filename="package://rover_description/meshes/63.stl" scale="1 1 1"/>
      </geometry>
    </collision>
  </link>
  <joint name="wheel_1_joint" type="continuous">
    <origin rpy="-3.13848 0 1.5708" xyz="-5.55112e-17 -0.109219 -0.0805"/>
    <axis xyz="-1 0 0"/>
    <parent link="main_body"/>
    <child link="wheel_1"/>
  </joint>
  <gazebo reference="wheel_1">
    <mu1>1.0</mu1>
    <mu2>1.0</mu2>
    <kp>100000.0</kp>
    <kd>1.0</kd>
  </gazebo>
  <link name="wheel">
    <inertial>
      <origin rpy="0 0 0" xyz="0.0133801 0 -0.00317342"/>
      <mass value="0.000126179"/>
      <inertia ixx="1.35094e-07" ixy="0" ixz="4.8002e-11" iyy="7.41754e-08" iyz="0" izz="7.43953e-08"/>
    </inertial>
    <visual>
      <origin rpy="0 0 0" xyz="0 0 0"/>
      <geometry>
        <mesh filename="package://rover_description/meshes/63.stl" scale="1 1 1"/>
      </geometry>
      <material name="body_color"/>
    </visual>
    <collision>
      <origin rpy="0 0 0" xyz="0 0 0"/>
      <geometry>
        <mesh filename="package://rover_description/meshes/63.stl" scale="1 1 1"/>
      </geometry>
    </collision>
  </link>
  <joint name="wheel_joint" type="continuous">
    <origin rpy="0.0299318 0 -1.5708" xyz="-5.55112e-17 0.113673 -0.0805"/>
    <axis xyz="1 0 0"/>
    <parent link="main_body"/>
    <child link="wheel"/>
  </joint>
  <gazebo reference="wheel">
    <mu1>1.0</mu1>
    <mu2>1.0</mu2>
    <kp>100000.0</kp>
    <kd>1.0</kd>
  </gazebo>
  <link name="wheel_3">
    <inertial>
      <origin rpy="0 0 0" xyz="0.0133801 0 -0.00317342"/>
      <mass value="0.000126179"/>
      <inertia ixx="1.35094e-07" ixy="0" ixz="4.8002e-11" iyy="7.41754e-08" iyz="0" izz="7.43953e-08"/>
    </inertial>
    <visual>
      <origin rpy="0 0 0" xyz="0 0 0"/>
      <geometry>
        <mesh filename="package://rover_description/meshes/63.stl" scale="1 1 1"/>
      </geometry>
      <material name="body_color"/>
    </visual>
    <collision>
      <origin rpy="0 0 0" xyz="0 0 0"/>
      <geometry>
        <mesh filename="package://rover_description/meshes/63.stl" scale="1 1 1"/>
      </geometry>
    </collision>
  </link>
  <joint name="wheel_3_joint" type="continuous">
    <origin rpy="0.81533 0 -1.5708" xyz="-0.165821 0.113673 -0.0805"/>
    <axis xyz="1 0 0"/>
    <parent link="main_body"/>
    <child link="wheel_3"/>
  </joint>
  <gazebo reference="wheel_3">
    <mu1>1.0</mu1>
    <mu2>1.0</mu2>
    <kp>100000.0</kp>
    <kd>1.0</kd>
  </gazebo>
</robot>
